Workbook

Sheet Sheet1
A1: No | B1: NIU | C1: Nama | D1: Tahun Masuk | E1: Tahun Lulus | F1: Email 1 | G1: Email 1
A2: 1 | B2: 3614 | C2: Hasjimy Masidin | D2: 1960 | E2: 1969 | F2: {=_xlfn.XLOOKUP(D2&C2, Sheet3!$C$2:$C$1224&Sheet3!$B$2:$B$1224, Sheet3!$D$2:$D$1224, "")} | G2: {=_xlfn.XLOOKUP(D2&C2, Sheet2!$A$2:$A$558&Sheet2!$B$2:$B$558, Sheet2!$C$2:$C$558, "")} | H2: =IF(F2<>"",F2,G2)
A3: 2 | B3: 4257 | C3: Haroetomo | D3: 1961 | E3: 1969 | F3: {=_xlfn.XLOOKUP(D3&C3, Sheet3!$C$2:$C$1224&Sheet3!$B$2:$B$1224, Sheet3!$D$2:$D$1224, "")} | G3: {=_xlfn.XLOOKUP(D3&C3, Sheet2!$A$2:$A$558&Sheet2!$B$2:$B$558, Sheet2!$C$2:$C$558, "")} | H3: =IF(F3<>"",F3,G3)
A4: 3 | B4: 3692 | C4: Prijono | D4: 1960 | E4: 1970 | F4: {=_xlfn.XLOOKUP(D4&C4, Sheet3!$C$2:$C$1224&Sheet3!$B$2:$B$1224, Sheet3!$D$2:$D$1224, "")} | G4: {=_xlfn.XLOOKUP(D4&C4, Sheet2!$A$2:$A$558&Sheet2!$B$2:$B$558, Sheet2!$C$2:$C$558, "")} | H4: =IF(F4<>"",F4,G4)
A5: 4 | B5: 3643 | C5: Rachmad PH. | D5: 1960 | E5: 1970 | F5: {=_xlfn.XLOOKUP(D5&C5, Sheet3!$C$2:$C$1224&Sheet3!$B$2:$B$1224, Sheet3!$D$2:$D$1224, "")} | G5: {=_xlfn.XLOOKUP(D5&C5, Sheet2!$A$2:$A$558&Sheet2!$B$2:$B$558, Sheet2!$C$2:$C$558, "")} | H5: =IF(F5<>"",F5,G5)
A6: 5 | B6: 3750 | C6: Soeminto | D6: 1960 | E6: 1970 | F6: {=_xlfn.XLOOKUP(D6&C6, Sheet3!$C$2:$C$1224&Sheet3!$B$2:$B$1224, Sheet3!$D$2:$D$1224, "")} | G6: {=_xlfn.XLOOKUP(D6&C6, Sheet2!$A$2:$A$558&Sheet2!$B$2:$B$558, Sheet2!$C$2:$C$558, "")} | H6: =IF(F6<>"",F6,G6)
A7: 6 | B7: 3709 | C7: Soebardi | D7: 1960 | E7: 1971 | F7: {=_xlfn.XLOOKUP(D7&C7, Sheet3!$C$2:$C$1224&Sheet3!$B$2:$B$1224, Sheet3!$D$2:$D$1224, "")} | G7: {=_xlfn.XLOOKUP(D7&C7, Sheet2!$A$2:$A$558&Sheet2!$B$2:$B$558, Sheet2!$C$2:$C$558, "")} | H7: =IF(F7<>"",F7,G7)
A8: 7 | B8: 3719 | C8: Soeprapto | D8: 1960 | E8: 1971 | F8: {=_xlfn.XLOOKUP(D8&C8, Sheet3!$C$2:$C$1224&Sheet3!$B$2:$B$1224, Sheet3!$D$2:$D$1224, "")} | G8: {=_xlfn.XLOOKUP(D8&C8, Sheet2!$A$2:$A$558&Sheet2!$B$2:$B$558, Sheet2!$C$2:$C$558, "")} | H8: =IF(F8<>"",F8,G8)
A9: 8 | B9: 3973 | C9: Iskandar Hidayat | D9: 1960 | E9: 1972 | F9: {=_xlfn.XLOOKUP(D9&C9, Sheet3!$C$2:$C$1224&Sheet3!$B$2:$B$1224, Sheet3!$D$2:$D$1224, "")} | G9: {=_xlfn.XLOOKUP(D9&C9, Sheet2!$A$2:$A$558&Sheet2!$B$2:$B$558, Sheet2!$C$2:$C$558, "")} | H9: =IF(F9<>"",F9,G9)
A10: 9 | B10: 4048 | C10: Djamhari | D10: 1961 | E10: 1972 | F10: {=_xlfn.XLOOKUP(D10&C10, Sheet3!$C$2:$C$1224&Sheet3!$B$2:$B$1224, Sheet3!$D$2:$D$1224, "")} | G10: {=_xlfn.XLOOKUP(D10&C10, Sheet2!$A$2:$A$558&Sheet2!$B$2:$B$558, Sheet2!$C$2:$C$558, "")} | H10: =IF(F10<>"",F10,G10)
A11: 10 | B11: 3746 | C11: Suharsana | D11: 1960 | E11: 1974 | F11: {=_xlfn.XLOOKUP(D11&C11, Sheet3!$C$2:$C$1224&Sheet3!$B$2:$B$1224, Sheet3!$D$2:$D$1224, "")} | G11: {=_xlfn.XLOOKUP(D11&C11, Sheet2!$A$2:$A$558&Sheet2!$B$2:$B$558, Sheet2!$C$2:$C$558, "")} | H11: =IF(F11<>"",F11,G11)
A12: 11 | B12: 3551 | C12: MARTOYO | D12: 1959 | E12: 1974 | F12: {=_xlfn.XLOOKUP(D12&C12, Sheet3!$C$2:$C$1224&Sheet3!$B$2:$B$1224, Sheet3!$D$2:$D$1224, "")} | G12: {=_xlfn.XLOOKUP(D12&C12, Sheet2!$A$2:$A$558&Sheet2!$B$2:$B$558, Sheet2!$C$2:$C$558, "")} | H12: =IF(F12<>"",F12,G12)
A13: 12 | B13: 3665 | C13: Soepono | D13: 1960 | E13: 1975 | F13: {=_xlfn.XLOOKUP(D13&C13, Sheet3!$C$2:$C$1224&Sheet3!$B$2:$B$1224, Sheet3!$D$2:$D$1224, "")} | G13: {=_xlfn.XLOOKUP(D13&C13, Sheet2!$A$2:$A$558&Sheet2!$B$2:$B$558, Sheet2!$C$2:$C$558, "")} | H13: =IF(F13<>"",F13,G13)
... A504: 503 | B504: 12682 | C504: R. R. Eny Putranti | D504: 1983 | E504: 1990 | F504: {=_xlfn.XLOOKUP(D504&C504, Sheet3!$C$2:$C$1224&Sheet3!$B$2:$B$1224, Sheet3!$D$2:$D$1224, "")} | G504: {=_xlfn.XLOOKUP(D504&C504, Sheet2!$A$2:$A$558&Sheet2!$B$2:$B$558, Sheet2!$C$2:$C$558, "")} | H504: =IF(F504<>"",F504,G504)
A505: 504 | B505: 13052 | C505: Bambang Gatot Nugroho | D505: 1984 | E505: 1990 | F505: {=_xlfn.XLOOKUP(D505&C505, Sheet3!$C$2:$C$1224&Sheet3!$B$2:$B$1224, Sheet3!$D$2:$D$1224, "")} -> b.gatotnugroho@gmail.com | G505: {=_xlfn.XLOOKUP(D505&C505, Sheet2!$A$2:$A$558&Sheet2!$B$2:$B$558, Sheet2!$C$2:$C$558, "")} -> b.gatotnugroho@gmail.com | H505: =IF(F505<>"",F505,G505) -> b.gatotnugroho@gmail.com
A506: 505 | B506: 12736 | C506: Marcus Sudarmaji | D506: 1984 | E506: 1990 | F506: {=_xlfn.XLOOKUP(D506&C506, Sheet3!$C$2:$C$1224&Sheet3!$B$2:$B$1224, Sheet3!$D$2:$D$1224, "")} | G506: {=_xlfn.XLOOKUP(D506&C506, Sheet2!$A$2:$A$558&Sheet2!$B$2:$B$558, Sheet2!$C$2:$C$558, "")} | H506: =IF(F506<>"",F506,G506)
A507: 506 | B507: 12739 | C507: Rochmat Muryamto | D507: 1984 | E507: 1990 | F507: {=_xlfn.XLOOKUP(D507&C507, Sheet3!$C$2:$C$1224&Sheet3!$B$2:$B$1224, Sheet3!$D$2:$D$1224, "")} | G507: {=_xlfn.XLOOKUP(D507&C507, Sheet2!$A$2:$A$558&Sheet2!$B$2:$B$558, Sheet2!$C$2:$C$558, "")} | H507: =IF(F507<>"",F507,G507)
A508: 507 | B508: 9078 | C508: Landung Kadaryanto | D508: 1976 | E508: 1990 | F508: {=_xlfn.XLOOKUP(D508&C508, Sheet3!$C$2:$C$1224&Sheet3!$B$2:$B$1224, Sheet3!$D$2:$D$1224, "")} | G508: {=_xlfn.XLOOKUP(D508&C508, Sheet2!$A$2:$A$558&Sheet2!$B$2:$B$558, Sheet2!$C$2:$C$558, "")} | H508: =IF(F508<>"",F508,G508)
A509: 508 | B509: 12879 | C509: Cipto Waluyo | D509: 1984 | E509: 1990 | F509: {=_xlfn.XLOOKUP(D509&C509, Sheet3!$C$2:$C$1224&Sheet3!$B$2:$B$1224, Sheet3!$D$2:$D$1224, "")} | G509: {=_xlfn.XLOOKUP(D509&C509, Sheet2!$A$2:$A$558&Sheet2!$B$2:$B$558, Sheet2!$C$2:$C$558, "")} | H509: =IF(F509<>"",F509,G509)
A510: 509 | B510: 12650 | C510: Muhamad Alief Yaniar | D510: 1983 | E510: 1990 | F510: {=_xlfn.XLOOKUP(D510&C510, Sheet3!$C$2:$C$1224&Sheet3!$B$2:$B$1224, Sheet3!$D$2:$D$1224, "")} | G510: {=_xlfn.XLOOKUP(D510&C510, Sheet2!$A$2:$A$558&Sheet2!$B$2:$B$558, Sheet2!$C$2:$C$558, "")} | H510: =IF(F510<>"",F510,G510)
A511: 510 | B511: 13258 | C511: Anthony | D511: 1985 | E511: 1990 | F511: {=_xlfn.XLOOKUP(D511&C511, Sheet3!$C$2:$C$1224&Sheet3!$B$2:$B$1224, Sheet3!$D$2:$D$1224, "")} | G511: {=_xlfn.XLOOKUP(D511&C511, Sheet2!$A$2:$A$558&Sheet2!$B$2:$B$558, Sheet2!$C$2:$C$558, "")} | H511: =IF(F511<>"",F511,G511)
A512: 511 | B512: 13020 | C512: Fauzan Murdapa | D512: 1984 | E512: 1990 | F512: {=_xlfn.XLOOKUP(D512&C512, Sheet3!$C$2:$C$1224&Sheet3!$B$2:$B$1224, Sheet3!$D$2:$D$1224, "")} | G512: {=_xlfn.XLOOKUP(D512&C512, Sheet2!$A$2:$A$558&Sheet2!$B$2:$B$558, Sheet2!$C$2:$C$558, "")} | H512: =IF(F512<>"",F512,G512)
A513: 512 | B513: 10006 | C513: Hanuri Effendi | D513: 1978 | E513: 1990 | F513: {=_xlfn.XLOOKUP(D513&C513, Sheet3!$C$2:$C$1224&Sheet3!$B$2:$B$1224, Sheet3!$D$2:$D$1224, "")} | G513: {=_xlfn.XLOOKUP(D513&C513, Sheet2!$A$2:$A$558&Sheet2!$B$2:$B$558, Sheet2!$C$2:$C$558, "")} | H513: =IF(F513<>"",F513,G513)
A514: 513 | B514: 12969 | C514: Retno Kusumastanti | D514: 1984 | E514: 1990 | F514: {=_xlfn.XLOOKUP(D514&C514, Sheet3!$C$2:$C$1224&Sheet3!$B$2:$B$1224, Sheet3!$D$2:$D$1224, "")} -> kusumastanti@gmail.com | G514: {=_xlfn.XLOOKUP(D514&C514, Sheet2!$A$2:$A$558&Sheet2!$B$2:$B$558, Sheet2!$C$2:$C$558, "")} | H514: =IF(F514<>"",F514,G514) -> kusumastanti@gmail.com
A515: 514 | B515: 7150 | C515: Marjudi | D515: 1971 | E515: 1990 | F515: {=_xlfn.XLOOKUP(D515&C515, Sheet3!$C$2:$C$1224&Sheet3!$B$2:$B$1224, Sheet3!$D$2:$D$1224, "")} | G515: {=_xlfn.XLOOKUP(D515&C515, Sheet2!$A$2:$A$558&Sheet2!$B$2:$B$558, Sheet2!$C$2:$C$558, "")} | H515: =IF(F515<>"",F515,G515)
A516: 515 | B516: 13256 | C516: Singgih Supriyanto | D516: 1985 | E516: 1990 | F516: {=_xlfn.XLOOKUP(D516&C516, Sheet3!$C$2:$C$1224&Sheet3!$B$2:$B$1224, Sheet3!$D$2:$D$1224, "")} -> singgih8213849@gmail.com | G516: {=_xlfn.XLOOKUP(D516&C516, Sheet2!$A$2:$A$558&Sheet2!$B$2:$B$558, Sheet2!$C$2:$C$558, "")} | H516: =IF(F516<>"",F516,G516) -> singgih8213849@gmail.com
A517: 516 | B517: 13126 | C517: Fransiscus Frito Marcevianto | D517: 1984 | E517: 1990 | F517: {=_xlfn.XLOOKUP(D517&C517, Sheet3!$C$2:$C$1224&Sheet3!$B$2:$B$1224, Sheet3!$D$2:$D$1224, "")} -> fritofrm@yahoo.co.id | G517: {=_xlfn.XLOOKUP(D517&C517, Sheet2!$A$2:$A$558&Sheet2!$B$2:$B$558, Sheet2!$C$2:$C$558, "")} | H517: =IF(F517<>"",F517,G517) -> fritofrm@yahoo.co.id
... A642: 641 | B642: 14409 | C642: Tandyo Winarno | D642: 1986 | E642: 1993 | F642: {=_xlfn.XLOOKUP(D642&C642, Sheet3!$C$2:$C$1224&Sheet3!$B$2:$B$1224, Sheet3!$D$2:$D$1224, "")} -> tandyo.winarno@gmail.com | G642: {=_xlfn.XLOOKUP(D642&C642, Sheet2!$A$2:$A$558&Sheet2!$B$2:$B$558, Sheet2!$C$2:$C$558, "")} -> tandyow@yahoo.com | H642: =IF(F642<>"",F642,G642) -> tandyo.winarno@gmail.com
A643: 642 | C643: Herra Fajarriawan | D643: 1985 | E643: 1993 | F643: {=_xlfn.XLOOKUP(D643&C643, Sheet3!$C$2:$C$1224&Sheet3!$B$2:$B$1224, Sheet3!$D$2:$D$1224, "")} | G643: {=_xlfn.XLOOKUP(D643&C643, Sheet2!$A$2:$A$558&Sheet2!$B$2:$B$558, Sheet2!$C$2:$C$558, "")} | H643: =IF(F643<>"",F643,G643)
A644: 643 | B644: 14443 | C644: Raden Sayuti | D644: 1986 | E644: 1993 | F644: {=_xlfn.XLOOKUP(D644&C644, Sheet3!$C$2:$C$1224&Sheet3!$B$2:$B$1224, Sheet3!$D$2:$D$1224, "")} | G644: {=_xlfn.XLOOKUP(D644&C644, Sheet2!$A$2:$A$558&Sheet2!$B$2:$B$558, Sheet2!$C$2:$C$558, "")} | H644: =IF(F644<>"",F644,G644)
A645: 644 | B645: 14428 | C645: Giri Budi Santoso | D645: 1986 | E645: 1993 | F645: {=_xlfn.XLOOKUP(D645&C645, Sheet3!$C$2:$C$1224&Sheet3!$B$2:$B$1224, Sheet3!$D$2:$D$1224, "")} | G645: {=_xlfn.XLOOKUP(D645&C645, Sheet2!$A$2:$A$558&Sheet2!$B$2:$B$558, Sheet2!$C$2:$C$558, "")} | H645: =IF(F645<>"",F645,G645)
A646: 645 | B646: 13176 | C646: Teguh Karyadi | D646: 1984 | E646: 1993 | F646: {=_xlfn.XLOOKUP(D646&C646, Sheet3!$C$2:$C$1224&Sheet3!$B$2:$B$1224, Sheet3!$D$2:$D$1224, "")} -> tegkaryadi@gmail.com | G646: {=_xlfn.XLOOKUP(D646&C646, Sheet2!$A$2:$A$558&Sheet2!$B$2:$B$558, Sheet2!$C$2:$C$558, "")} | H646: =IF(F646<>"",F646,G646) -> tegkaryadi@gmail.com
A647: 646 | B647: 13578 | C647: Setiyawan Utama | D647: 1985 | E647: 1993 | F647: {=_xlfn.XLOOKUP(D647&C647, Sheet3!$C$2:$C$1224&Sheet3!$B$2:$B$1224, Sheet3!$D$2:$D$1224, "")} | G647: {=_xlfn.XLOOKUP(D647&C647, Sheet2!$A$2:$A$558&Sheet2!$B$2:$B$558, Sheet2!$C$2:$C$558, "")} | H647: =IF(F647<>"",F647,G647)
A648: 647 | B648: 14434 | C648: Amin Widada Lestariya | D648: 1986 | E648: 1993 | F648: {=_xlfn.XLOOKUP(D648&C648, Sheet3!$C$2:$C$1224&Sheet3!$B$2:$B$1224, Sheet3!$D$2:$D$1224, "")} -> aminwidada@gmail.com | G648: {=_xlfn.XLOOKUP(D648&C648, Sheet2!$A$2:$A$558&Sheet2!$B$2:$B$558, Sheet2!$C$2:$C$558, "")} | H648: =IF(F648<>"",F648,G648) -> aminwidada@gmail.com
A649: 648 | B649: 11750 | C649: Heru Asmoro | D649: 1982 | E649: 1993 | F649: {=_xlfn.XLOOKUP(D649&C649, Sheet3!$C$2:$C$1224&Sheet3!$B$2:$B$1224, Sheet3!$D$2:$D$1224, "")} | G649: {=_xlfn.XLOOKUP(D649&C649, Sheet2!$A$2:$A$558&Sheet2!$B$2:$B$558, Sheet2!$C$2:$C$558, "")} | H649: =IF(F649<>"",F649,G649)
A650: 649 | B650: 14589 | C650: Citrawati | D650: 1987 | E650: 1993 | F650: {=_xlfn.XLOOKUP(D650&C650, Sheet3!$C$2:$C$1224&Sheet3!$B$2:$B$1224, Sheet3!$D$2:$D$1224, "")} -> citraprakoso@gmail.com | G650: {=_xlfn.XLOOKUP(D650&C650, Sheet2!$A$2:$A$558&Sheet2!$B$2:$B$558, Sheet2!$C$2:$C$558, "")} -> citraprakoso@gmail.com | H650: =IF(F650<>"",F650,G650) -> citraprakoso@gmail.com
A651: 650 | B651: 14420 | C651: Agung Muhammad Prakoso | D651: 1986 | E651: 1993 | F651: {=_xlfn.XLOOKUP(D651&C651, Sheet3!$C$2:$C$1224&Sheet3!$B$2:$B$1224, Sheet3!$D$2:$D$1224, "")} -> amprakoso@gmail.com | G651: {=_xlfn.XLOOKUP(D651&C651, Sheet2!$A$2:$A$558&Sheet2!$B$2:$B$558, Sheet2!$C$2:$C$558, "")} -> amprakoso@gmail.com | H651: =IF(F651<>"",F651,G651) -> amprakoso@gmail.com
A652: 651 | B652: 14308 | C652: I Dewa Ketut Spatika | D652: 1986 | E652: 1993 | F652: {=_xlfn.XLOOKUP(D652&C652, Sheet3!$C$2:$C$1224&Sheet3!$B$2:$B$1224, Sheet3!$D$2:$D$1224, "")} | G652: {=_xlfn.XLOOKUP(D652&C652, Sheet2!$A$2:$A$558&Sheet2!$B$2:$B$558, Sheet2!$C$2:$C$558, "")} | H652: =IF(F652<>"",F652,G652)
A653: 652 | B653: 13787 | C653: Tri Rayono | D653: 1985 | E653: 1993 | F653: {=_xlfn.XLOOKUP(D653&C653, Sheet3!$C$2:$C$1224&Sheet3!$B$2:$B$1224, Sheet3!$D$2:$D$1224, "")} -> rayonotri@gmail | G653: {=_xlfn.XLOOKUP(D653&C653, Sheet2!$A$2:$A$558&Sheet2!$B$2:$B$558, Sheet2!$C$2:$C$558, "")} | H653: =IF(F653<>"",F653,G653) -> rayonotri@gmail
A654: 653 | B654: 12957 | C654: Rachmad | D654: 1984 | E654: 1993 | F654: {=_xlfn.XLOOKUP(D654&C654, Sheet3!$C$2:$C$1224&Sheet3!$B$2:$B$1224, Sheet3!$D$2:$D$1224, "")} | G654: {=_xlfn.XLOOKUP(D654&C654, Sheet2!$A$2:$A$558&Sheet2!$B$2:$B$558, Sheet2!$C$2:$C$558, "")} | H654: =IF(F654<>"",F654,G654)
...

Sheet Sheet2
A1: Angkatan | B1: Nama | C1: Email
A2: 1989 | B2: Muchammad Sigit Widodo | C2: 1sigit.widodo@gmail.com | D2: =IF(COUNTIFS(Sheet1!$D$2:$D$3203, A2, Sheet1!$C$2:$C$3203, B2) > 0, "Sudah", "Belum") -> Sudah
A3: 1991 | B3: Aji Tri Martono | C3: a_trimartanto@yahoo.com | D3: =IF(COUNTIFS(Sheet1!$D$2:$D$3203, A3, Sheet1!$C$2:$C$3203, B3) > 0, "Sudah", "Belum") -> Sudah
A4: 1999 | B4: Aulia Akbar | C4: a.akbar.idn@gmail.com | D4: =IF(COUNTIFS(Sheet1!$D$2:$D$3203, A4, Sheet1!$C$2:$C$3203, B4) > 0, "Sudah", "Belum") -> Sudah
A5: 1999 | B5: April Tonapa | C5: a.tonapa@gmail.com | D5: =IF(COUNTIFS(Sheet1!$D$2:$D$3203, A5, Sheet1!$C$2:$C$3203, B5) > 0, "Sudah", "Belum") -> Sudah
A6: 2007 | B6: Abdussalam Hidayat | C6: aamgoin@gmail.com | D6: =IF(COUNTIFS(Sheet1!$D$2:$D$3203, A6, Sheet1!$C$2:$C$3203, B6) > 0, "Sudah", "Belum") -> Sudah
A7: 1995 | B7: BLASIUS ANGGORO YUWONO | C7: aangku@yahoo.com | D7: =IF(COUNTIFS(Sheet1!$D$2:$D$3203, A7, Sheet1!$C$2:$C$3203, B7) > 0, "Sudah", "Belum") -> Sudah
A8: 2017 | B8: Abdurrohman Rizal | C8: abdurrohmanrizal25@gmail.com | D8: =IF(COUNTIFS(Sheet1!$D$2:$D$3203, A8, Sheet1!$C$2:$C$3203, B8) > 0, "Sudah", "Belum") -> Sudah
A9: 2005 | B9: Achmad Bachtiar Firman | C9: achmadbfirman@gmail.com | D9: =IF(COUNTIFS(Sheet1!$D$2:$D$3203, A9, Sheet1!$C$2:$C$3203, B9) > 0, "Sudah", "Belum") -> Sudah
A10: 1998 | B10: Dony Novantoro | C10: adelinegolda@yahoo.com | D10: =IF(COUNTIFS(Sheet1!$D$2:$D$3203, A10, Sheet1!$C$2:$C$3203, B10) > 0, "Sudah", "Belum") -> Sudah
A11: 2005 | B11: Adhi Wirawan | C11: adhi.geodesi@gmail.com | D11: =IF(COUNTIFS(Sheet1!$D$2:$D$3203, A11, Sheet1!$C$2:$C$3203, B11) > 0, "Sudah", "Belum") -> Sudah
A12: 2000 | B12: Adhityo susilo nugroho | C12: adhityo.susilo@gmail.com | D12: =IF(COUNTIFS(Sheet1!$D$2:$D$3203, A12, Sheet1!$C$2:$C$3203, B12) > 0, "Sudah", "Belum") -> Sudah
A13: 2003 | B13: Aditya Yan Paradita | C13: adityayanp@gmail.com | D13: =IF(COUNTIFS(Sheet1!$D$2:$D$3203, A13, Sheet1!$C$2:$C$3203, B13) > 0, "Sudah", "Belum") -> Sudah
... A529: 2013 | B529: Ghotfani Kaukabi | C529: ghotfani.kaukabi@gmail.com | D529: =IF(COUNTIFS(Sheet1!$D$2:$D$3203, A529, Sheet1!$C$2:$C$3203, B529) > 0, "Sudah", "Belum") -> Sudah
A530: Ext - 2006 | B530: Muhammad Ismail Pringgkusumo | C530: caesar_ael@yahoo.com | D530: =IF(COUNTIFS(Sheet1!$D$2:$D$3203, A530, Sheet1!$C$2:$C$3203, B530) > 0, "Sudah", "Belum") -> Belum
A531: 1998 | B531: Agus Prasetyanto | C531: agus98prasetyanto@gmail.com | D531: =IF(COUNTIFS(Sheet1!$D$2:$D$3203, A531, Sheet1!$C$2:$C$3203, B531) > 0, "Sudah", "Belum") -> Sudah
A532: 2019 | B532: Arinda Tasya Avrianti | C532: arindatasya01@mail.ugm.ac.id | D532: =IF(COUNTIFS(Sheet1!$D$2:$D$3203, A532, Sheet1!$C$2:$C$3203, B532) > 0, "Sudah", "Belum") -> Sudah
A533: 2019 | B533: Azkal Azkiya | C533: azkalazkiya1@gmail.com | D533: =IF(COUNTIFS(Sheet1!$D$2:$D$3203, A533, Sheet1!$C$2:$C$3203, B533) > 0, "Sudah", "Belum") -> Belum
A534: 2020 | B534: Khozy Ilyasyah Zalmajati | C534: kokozalmajati@gmail.com | D534: =IF(COUNTIFS(Sheet1!$D$2:$D$3203, A534, Sheet1!$C$2:$C$3203, B534) > 0, "Sudah", "Belum") -> Belum
A535: 2020 | B535: Aji Sugiantoro | C535: ajisugiantoro2415@gmail.com | D535: =IF(COUNTIFS(Sheet1!$D$2:$D$3203, A535, Sheet1!$C$2:$C$3203, B535) > 0, "Sudah", "Belum") -> Sudah
A536: 2019 | B536: Anisa'ul Khoiriyah Afandi | C536: anisaulkhoiriyah@mail.ugm.ac.id | D536: =IF(COUNTIFS(Sheet1!$D$2:$D$3203, A536, Sheet1!$C$2:$C$3203, B536) > 0, "Sudah", "Belum") -> Sudah
A537: 2019 | B537: Nur Aisyah Lutfi Fatmawati | C537: naisyah666@mail.ugm.ac.id | D537: =IF(COUNTIFS(Sheet1!$D$2:$D$3203, A537, Sheet1!$C$2:$C$3203, B537) > 0, "Sudah", "Belum") -> Sudah
A538: 2020 | B538: Assyfa Hesa Maharani | C538: assyfahesa2020@mail.ugm.ac.id | D538: =IF(COUNTIFS(Sheet1!$D$2:$D$3203, A538, Sheet1!$C$2:$C$3203, B538) > 0, "Sudah", "Belum") -> Sudah
A539: 2015 | B539: Farahmitha Aulia Prijadi | C539: prijadifarahmitha@gmail.com | D539: =IF(COUNTIFS(Sheet1!$D$2:$D$3203, A539, Sheet1!$C$2:$C$3203, B539) > 0, "Sudah", "Belum") -> Sudah
A540: 1995 | B540: Moh. Qisthi Amarona | C540: qisthi.amarona@gmail.com | D540: =IF(COUNTIFS(Sheet1!$D$2:$D$3203, A540, Sheet1!$C$2:$C$3203, B540) > 0, "Sudah", "Belum") -> Sudah
A541: 1991 | B541: Farid Hidayat | C541: farid.jaktara@gmail.com | D541: =IF(COUNTIFS(Sheet1!$D$2:$D$3203, A541, Sheet1!$C$2:$C$3203, B541) > 0, "Sudah", "Belum") -> Sudah
A542: 1995 | B542: Variawati | C542: variawati@gmail.com | D542: =IF(COUNTIFS(Sheet1!$D$2:$D$3203, A542, Sheet1!$C$2:$C$3203, B542) > 0, "Sudah", "Belum") -> Sudah
... A558: 1998 | B558: Dedi Atunggal Sp | C558: dediatunggal@ugm.ac.id | D558: =IF(COUNTIFS(Sheet1!$D$2:$D$3203, A558, Sheet1!$C$2:$C$3203, B558) > 0, "Sudah", "Belum") -> Sudah

Sheet Sheet3
B1: Nama | C1: Angkatan | D1: Email | E1: No Telp / WA | F1: Column1
A2: 1 | B2: Zudiantoro | C2: 1994 | D2: Zuditax@gmail.com | E2: 08127906633 | F2: =IF(COUNTIFS(Sheet1!$D$2:$D$3203, C2, Sheet1!$C$2:$C$3203, B2) > 0, "Sudah", "Belum") -> Sudah
A3: 2 | B3: Dahliani | C3: 1990 | D3: Lia.Roedji@gmail.com | E3: 081297584822 | F3: =IF(COUNTIFS(Sheet1!$D$2:$D$3203, C3, Sheet1!$C$2:$C$3203, B3) > 0, "Sudah", "Belum") -> Sudah
A4: 3 | B4: Novi Trihastuti | C4: 1994 | D4: ntrihastuti2021@gmail.com | E4: 0811887538 | F4: =IF(COUNTIFS(Sheet1!$D$2:$D$3203, C4, Sheet1!$C$2:$C$3203, B4) > 0, "Sudah", "Belum") -> Sudah
A5: 4 | B5: Fakhrurrazi | C5: 1989 | D5: ojiktgd@gmail.com | E5: 082123359959 | F5: =IF(COUNTIFS(Sheet1!$D$2:$D$3203, C5, Sheet1!$C$2:$C$3203, B5) > 0, "Sudah", "Belum") -> Sudah
A6: 5 | B6: Prilnali Eka Putra | C6: 2003 | D6: prilnali.eka@gmail.com | E6: 081226953100 | F6: =IF(COUNTIFS(Sheet1!$D$2:$D$3203, C6, Sheet1!$C$2:$C$3203, B6) > 0, "Sudah", "Belum") -> Sudah
A7: 6 | B7: Riza Pramudya | C7: 1990 | D7: rizapramudya72@gmail.com | E7: 087812433972 | F7: =IF(COUNTIFS(Sheet1!$D$2:$D$3203, C7, Sheet1!$C$2:$C$3203, B7) > 0, "Sudah", "Belum") -> Sudah
A8: 7 | B8: Baron Yuri Setiawan | C8: 1994 | D8: Angingunung1@gmail.com | E8: 08153890045 | F8: =IF(COUNTIFS(Sheet1!$D$2:$D$3203, C8, Sheet1!$C$2:$C$3203, B8) > 0, "Sudah", "Belum") -> Sudah
A9: 8 | B9: Niajeng Pramesti | C9: 2004 | D9: niajengp@gmail.com | E9: 089695016457 | F9: =IF(COUNTIFS(Sheet1!$D$2:$D$3203, C9, Sheet1!$C$2:$C$3203, B9) > 0, "Sudah", "Belum") -> Sudah
A10: 9 | B10: Wahyu Daryatin | C10: 1994 | D10: wahyudhe@gmail.com | E10: 089629923698 | F10: =IF(COUNTIFS(Sheet1!$D$2:$D$3203, C10, Sheet1!$C$2:$C$3203, B10) > 0, "Sudah", "Belum") -> Sudah
A11: 10 | B11: Calvin Wijaya | C11: 2018 | D11: calvinwjy81@gmail.com | E11: 08117481709 | F11: =IF(COUNTIFS(Sheet1!$D$2:$D$3203, C11, Sheet1!$C$2:$C$3203, B11) > 0, "Sudah", "Belum") -> Sudah
A12: 11 | B12: MULYA SINA DIPUTRA | C12: 2007 | D12: mulyasina@gmail.com | E12: 08567645323 | F12: =IF(COUNTIFS(Sheet1!$D$2:$D$3203, C12, Sheet1!$C$2:$C$3203, B12) > 0, "Sudah", "Belum") -> Sudah
A13: 12 | B13: Agus indra gunawan | C13: 1997 | D13: agusindragunawan79@gmail.com | E13: 082155202005 | F13: =IF(COUNTIFS(Sheet1!$D$2:$D$3203, C13, Sheet1!$C$2:$C$3203, B13) > 0, "Sudah", "Belum") -> Sudah
... A1015: 1014 | B1015: Prasetyo Wibowo | C1015: 1999 | D1015: Prasbow@gmail.com | E1015: 081213860009 | F1015: =IF(COUNTIFS(Sheet1!$D$2:$D$3203, C1015, Sheet1!$C$2:$C$3203, B1015) > 0, "Sudah", "Belum") -> Sudah
A1016: 1015 | B1016: Halim Wiranata | C1016: 2011 | D1016: sosmedhalim@gmail.com | E1016: 83867212712 | F1016: =IF(COUNTIFS(Sheet1!$D$2:$D$3203, C1016, Sheet1!$C$2:$C$3203, B1016) > 0, "Sudah", "Belum") -> Sudah
A1017: 1016 | B1017: Siska Ria Andriyani | C1017: 1998 | D1017: siska.ria7@gmail.com | E1017: 081367014860 | F1017: =IF(COUNTIFS(Sheet1!$D$2:$D$3203, C1017, Sheet1!$C$2:$C$3203, B1017) > 0, "Sudah", "Belum") -> Sudah
A1018: 1017 | B1018: Phisca Yudha Pratama | C1018: 2007 | D1018: Phisca.pratama@gmail.com | E1018: 085643525566 | F1018: =IF(COUNTIFS(Sheet1!$D$2:$D$3203, C1018, Sheet1!$C$2:$C$3203, B1018) > 0, "Sudah", "Belum") -> Sudah
A1019: 1018 | B1019: Aditya Dimas Dewanto | C1019: 1998 | D1019: 2121adityadimas@gmail.com | E1019: 08121572121 | F1019: =IF(COUNTIFS(Sheet1!$D$2:$D$3203, C1019, Sheet1!$C$2:$C$3203, B1019) > 0, "Sudah", "Belum") -> Sudah
A1020: 1019 | B1020: Faqih Rohmatulloh | C1020: 2014 | D1020: frohmatulloh@gmail.com | E1020: 083870024576 | F1020: =IF(COUNTIFS(Sheet1!$D$2:$D$3203, C1020, Sheet1!$C$2:$C$3203, B1020) > 0, "Sudah", "Belum") -> Sudah
A1021: 1020 | B1021: Noviyanto purnomohadi | C1021: 1999 | D1021: noviyanto1811@gmail.com | E1021: 087836050009 | F1021: =IF(COUNTIFS(Sheet1!$D$2:$D$3203, C1021, Sheet1!$C$2:$C$3203, B1021) > 0, "Sudah", "Belum") -> Sudah
A1022: 1021 | B1022: Syafrisar Masri Limart | C1022: 2000 | D1022: masri.limart@gmail.com | E1022: 082171990099 | F1022: =IF(COUNTIFS(Sheet1!$D$2:$D$3203, C1022, Sheet1!$C$2:$C$3203, B1022) > 0, "Sudah", "Belum") -> Sudah
A1023: 1022 | B1023: Windiarto | C1023: 2009 | D1023: windiarto64@gmail.com | E1023: 085290589363 | F1023: =IF(COUNTIFS(Sheet1!$D$2:$D$3203, C1023, Sheet1!$C$2:$C$3203, B1023) > 0, "Sudah", "Belum") -> Sudah
A1024: 1023 | B1024: Vernika Silviana | C1024: 2020 | D1024: vernikasilviana@mail.ugm.ac.id | E1024: 082220870552 | F1024: =IF(COUNTIFS(Sheet1!$D$2:$D$3203, C1024, Sheet1!$C$2:$C$3203, B1024) > 0, "Sudah", "Belum") -> Sudah
A1025: 1024 | B1025: Yulieta | C1025: 1999 | D1025: yulietaaji@gmail.com | E1025: 081352710395 | F1025: =IF(COUNTIFS(Sheet1!$D$2:$D$3203, C1025, Sheet1!$C$2:$C$3203, B1025) > 0, "Sudah", "Belum") -> Sudah
A1026: 1025 | B1026: Ussisa Annisari | C1026: 2010 | D1026: ussisaannisari@yahoo.com | E1026: 085223724552 | F1026: =IF(COUNTIFS(Sheet1!$D$2:$D$3203, C1026, Sheet1!$C$2:$C$3203, B1026) > 0, "Sudah", "Belum") -> Sudah
A1027: 1026 | B1027: Titis Listyowati | C1027: 2001 | D1027: listyowatititis@gmail.com | E1027: 082324908571 | F1027: =IF(COUNTIFS(Sheet1!$D$2:$D$3203, C1027, Sheet1!$C$2:$C$3203, B1027) > 0, "Sudah", "Belum") -> Sudah
A1028: 1027 | B1028: Winda Kurniawati | C1028: 2010 | D1028: Winda.kurniawati92@gmail.com | E1028: 081231158473 | F1028: =IF(COUNTIFS(Sheet1!$D$2:$D$3203, C1028, Sheet1!$C$2:$C$3203, B1028) > 0, "Sudah", "Belum") -> Sudah
... A1224: 1223 | B1224: Ady Sihol Turnip | C1224: 1998 | D1224: turnip.adysihol@gmail.com | E1224: 08116126928 | F1224: =IF(COUNTIFS(Sheet1!$D$2:$D$3203, C1224, Sheet1!$C$2:$C$3203, B1224) > 0, "Sudah", "Belum") -> Sudah
D1226: Sudah | E1226: Sudah | F1226: =COUNTIF(Sigit_Rachmawan_Adhi[Column1],E1226) -> 1140
D1227: Belum | E1227: Belum | F1227: =COUNTIF(Sigit_Rachmawan_Adhi[Column1],E1227) -> 83
D1228: Total | F1228: =SUM(F1226:F1227) -> 1223
